Workbook
Name НЯХ: 'План счетов'!$A$2:$A$972
Name НЯХ: #REF!

Sheet План счетов
A1: № | B1: Номгўи њисобњо | C1: Рамзи сатр
A2: «1 11 110» | B2: Воситаҳои пулӣ бо асъори миллӣ | C2: 1 | D2: Денежные средства в национальной валюте | E2: касса
A3: «1 11 120» | B3: Воситаҳои пулӣ бо асъори хориҷӣ | C3: 1
A4: «1 11 130» | B4: Чекҳо бо асъори миллӣ | C4: 1
A5: «1 11 140» | B5: Чекҳо бо асъори хориҷӣ | C5: 1
A6: «1 11 141» | B6: Чекҳо бо рубли русӣ | C6: 1
A7: «1 11 142» | B7: Чекҳо бо доллари ИМА | C7: 1
A8: «1 11 143» | B8: Чекҳо бо Евро | C8: 1
A9: «1 11 210» | B9: ҲЯХ-и Буҷети ҷумҳуриявӣ (БҶ) бо асъори миллӣ | C9: 1
A10: «1 11 220» | B10: ҲЯХ-и Буҷети маҳаллӣ (БМ) бо асъори миллӣ | C10: 1
A11: «1 11 231» | B11: ҲЯХ-и ҳисоби махсуси БҶ бо асъори миллӣ – маблағҳои ташкилотҳои буҷетӣ (МТБ) | C11: 1
A12: «1 11 239» | B12: ҲЯХ-и ҳисоби махсуси БҶ бо асъори миллӣ - маблағҳои муайяннашуда (ММН) | C12: 1
A13: «1 11 241» | B13: ҲЯХ-и ҳисоби махсуси БМ бо асъори миллӣ – маблағҳои ташкилотҳои буҷетӣ (МТБ) | C13: 1
A14: «1 11 249» | B14: ҲЯХ-и ҳисоби махсуси БМ бо асъори миллӣ - маблағҳои муайяннашуда (ММН) | C14: 1
... A17: «1 11 253» | B17: ҲЯХ-и ҳисобҳои шахсии маблағҳои буҷетии БҶ ташкилотҳои буҷетӣ бо асъори миллӣ | C17: 1
A18: «1 11 254» | B18: ҲЯХ-и ҳисобҳои шахсии маблағҳои буҷетии БМ ташкилотҳои буҷетӣ бо асъори миллӣ | C18: 1 | D18: ЕКС лицевых счетов бюджетных средств МБ бюджетных организаций в национальной валюте | E18: Банк
A19: «1 11 255» | B19: Њисоби ягонаи хазинадории (ЊЯХ) њисобњои шахсии маблаѓњои буљетии Агентии суѓуртаи иљтимої ва нафаќа (АСИН) бо асъои миллї | C19: 1
A20: «1 11 260» | B20: Ҳисоби маблағҳои ФҲИА бо асъори миллӣ | C20: 1
A21: «1 11 270» | B21: Ҳисоби интиколии БҶ бо асъори миллӣ | C21: 1
A22: «1 11 280» | B22: Маблаѓњо барои нигоњдории дастгоњи марказии АСИН | C22: 1
A23: «1 11 310» | B23: ҲЯХ-и буҷети ҷумҳуриявӣ (БҶ) бо асъори хориҷӣ | C23: 1
A24: «1 11 320» | B24: ҲЯХ-и буҷети маҳаллӣ (БМ) бо асъори хориҷӣ | C24: 1
A25: «1 11 330» | B25: ҲЯХ-и ҳисоби махсуси БҶ бо асъори хориҷӣ | C25: 1
A26: «1 11 340» | B26: ҲЯХ-и ҳисоби махсуси БМ бо асъори хориҷӣ | C26: 1
A27: «1 11 350» | B27: ҲЯХ-и ҳисобҳои шахсии ташкилотҳои буҷетӣ бо асъори хориҷӣ | C27: 1
A28: «1 11 351» | B28: ҲЯХ-и ҳисобҳои шахсии ташкилотҳои буҷетӣ бо асъори хориҷӣ – БҶ | C28: 1
A29: «1 11 352» | B29: ҲЯХ-и ҳисобҳои шахсии ташкилотҳои буҷетӣ бо асъори хориҷӣ – маблағҳои махсуси БҶ | C29: 1
A30: «1 11 353» | B30: ҲЯХ-и ҳисобҳои шахсии ташкилотҳои буҷетӣ бо асъори хориҷӣ – маблағҳои БМ | C30: 1
... A93: «1 14 540» | B93: Ҳақи саҳмҳо барои қабул - асъори хориҷӣ | C93: 2
A94: «1 14 610» | B94: Қарздориҳои дебитории шахсҳои ҳисобдеҳ | C94: 2 | D94: =B94 -> Қарздориҳои дебитории шахсҳои ҳисобдеҳ | E94: 10520
A95: «1 14 620» | B95: Қарздориҳои дебитории ҳайати кормандон марбут ба музди меҳнат ва пардохтҳои дигар | C95: 2
A96: «1 14 630» | B96: Қарздориҳои дебитории марбут ба норасоиҳои ошкоршуда | C96: 2
A97: «1 14 700» | B97: Пардохтҳои иҷоравӣ барои қабул | C97: 2
A98: «1 14 800» | B98: Қисми ҷории қарздории дебитории дарозмуддат | C98: 2
A99: «1 14 900» | B99: Қарздории дебиторӣ аз рӯи дигар амалиётхо | C99: 2
A100: «1 15 100» | B100: Пешпардохтҳои додашуда барои молхо | C100: 4
A101: «1 15 200» | B101: Пешпардохтҳои додашуда барои иљрои кор ва хизматрасониҳо | C101: 4
A102: «1 15 300» | B102: Пешпардохтҳои додашуда барои иҷора | C102: 4
A103: «1 15 400» | B103: Пешпардохтҳо барои андоз | C103: 4
A104: «1 15 510» | B104: Пешпардохтҳои Хазинадорӣ оиди пардохдҳои ҷубронӣ, кўмакпулӣ | C104: 4
...

Sheet ОСВ
B2: Вид счёта | D2: № | E2: Номгуй | F2: Сальдо 01.01.26 | H2: Гардиши давра | J2: Сальдо 31.01.26
F3: Дт | G3: Кт | H3: Дт | I3: Кт | J3: Дт | K3: Кт
B4: Активный счёт | D4: ='План счетов'!A2 -> «1 11 110» | E4: ='План счетов'!B2 -> Воситаҳои пулӣ бо асъори миллӣ | F4: =602566-499310 -> 103256 | H4: 143000 | I4: 25200 | J4: =F4+H4-I4 -> 221056
D5: ='План счетов'!A18 -> «1 11 254» | E5: ='План счетов'!B18 -> ҲЯХ-и ҳисобҳои шахсии маблағҳои буҷетии БМ ташкилотҳои буҷетӣ бо асъори миллӣ | F5: 122366 | H5: 201062 | J5: =F5+H5-I5 -> 323428
D6: ='План счетов'!A138 -> «1 23 100» | E6: ='План счетов'!B138 -> Ҳисобҳо барои қабул
D7: ='План счетов'!A94 -> «1 14 610» | E7: ='План счетов'!B94 -> Қарздориҳои дебитории шахсҳои ҳисобдеҳ
D8: ='План счетов'!A100 -> «1 15 100» | E8: ='План счетов'!B100 -> Пешпардохтҳои додашуда барои молхо
D9: ='План счетов'!A101 -> «1 15 200» | E9: ='План счетов'!B101 -> Пешпардохтҳои додашуда барои иљрои кор ва хизматрасониҳо
D10: ='План счетов'!A102 -> «1 15 300» | E10: ='План счетов'!B102 -> Пешпардохтҳои додашуда барои иҷора
D11: ='План счетов'!A106 -> «1 15 900» | E11: ='План счетов'!B106 -> Дигар пешпардохтҳои додашуда
D12: ='План счетов'!A155 -> «1 31 120» | E12: ='План счетов'!B155 -> Захираҳои озуқаворӣ
D13: ='План счетов'!A156 -> «1 31 210» | E13: ='План счетов'!B156 -> Молҳои канселярӣ ва асбобҳои таълимӣ
D14: ='План счетов'!A157 -> «1 31 211» | E14: ='План счетов'!B157 -> Молҳои хоҷагӣ ва инвентар
D15: ='План счетов'!A158 -> «1 31 212» | E15: ='План счетов'!B158 -> Маводҳои хароҷотӣ
D16: ='План счетов'!A159 -> «1 31 213» | E16: ='План счетов'!B159 -> Инвентари мулоим ва либоси расмӣ
D17: ='План счетов'!A160 -> «1 31 214» | E17: ='План счетов'!B160 -> Маҳсулоти хўрока
D18: ='План счетов'!A162 -> «1 31 216» | E18: ='План счетов'!B162 -> Сўзишворӣ-равғанҳои молиданӣ
D19: ='План счетов'!A163 -> «1 31 217» | E19: ='План счетов'!B163 -> Сўзишворӣ дар ҳисоботдиҳии ронандагон
D20: ='План счетов'!A164 -> «1 31 218» | E20: ='План счетов'!B164 -> Истифодабарии захираҳои молӣ-маводӣ (ЗММ)
D21: ='План счетов'!A165 -> «1 31 219» | E21: ='План счетов'!B165 -> Молҳои дигаре, ки ба дараҷаҳои дигар мансубнадошта
D22: ='План счетов'!A166 -> «1 31 220» | E22: ='План счетов'!B166 -> Истеҳсолоти нотамом
D23: ='План счетов'!A167 -> «1 31 230» | E23: ='План счетов'!B167 -> Маҳсулоти тайёр
C24: Основные средства | D24: ='План счетов'!A170 -> «1 41 110» | E24: ='План счетов'!B170 -> Биноҳои истиқоматӣ (истиқоматгоҳ)
D25: ='План счетов'!A171 -> «1 41 120» | E25: ='План счетов'!B171 -> Биноҳои ғайриистиқоматӣ | F25: 200000 | J25: =F25+H25-I25 -> 200000
D26: ='План счетов'!A172 -> «1 41 210» | E26: ='План счетов'!B172 -> Иншоот | F26: 200000 | J26: =F26+H26-I26 -> 200000
D27: ='План счетов'!A173 -> «1 41 220» | E27: ='План счетов'!B173 -> Дастгоҳҳои таҳвилдиҳӣ | F27: 25000 | J27: =F27+H27-I27 -> 25000
D28: ='План счетов'!A174 -> «1 41 310» | E28: ='План счетов'!B174 -> Таҷҳизоти нақлиётӣ | F28: 15500 | J28: =F28+H28-I28 -> 15500
D29: ='План счетов'!A175 -> «1 41 320» | E29: ='План счетов'!B175 -> Дигар мошинҳо ва таҷҳизот
D30: ='План счетов'!A176 -> «1 41 400» | E30: ='План счетов'!B176 -> Мебел, лавозимоти идора,асбобҳо, инвентари истеҳсолӣ ва хоҷагидорӣ | F30: 55000 | J30: =F30+H30-I30 -> 55000
D31: ='План счетов'!A177 -> «1 41 500» | E31: ='План счетов'!B177 -> Ободонии замин
B32: Контрактивный счёт | C32: Износ / амортизация | D32: ='План счетов'!A178 -> «1 42 110» | E32: ='План счетов'!B178 -> Фарсудашавии ҷамъшуда - биноҳои истиқоматӣ
D33: ='План счетов'!A179 -> «1 42 120» | E33: ='План счетов'!B179 -> Фарсудашавии ҷамъшуда - биноҳои ғайриистиқоматӣ | G33: 25522 | I33: 2500 | K33: =G33+I33-H33 -> 28022
D34: ='План счетов'!A180 -> «1 42 210» | E34: ='План счетов'!B180 -> Фарсудашавии ҷамъшуда - иншоот | G34: 25522 | I34: 2500 | K34: =G34+I34-H34 -> 28022
D35: ='План счетов'!A181 -> «1 42 220» | E35: ='План счетов'!B181 -> Фарсудашавии ҷамъшуда - иншоот | G35: 2500 | I35: 400 | K35: =G35+I35-H35 -> 2900
D36: ='План счетов'!A182 -> «1 42 310» | E36: ='План счетов'!B182 -> Фарсудашавии ҷамъшуда - таҷҳизоти нақлиётӣ | G36: 1500 | I36: 300 | K36: =G36+I36-H36 -> 1800
D37: ='План счетов'!A183 -> «1 42 320» | E37: ='План счетов'!B183 -> Фарсудашавии ҷамъшуда - дигар мошинҳо ва таҷҳизот
D38: ='План счетов'!A184 -> «1 42 400» | E38: ='План счетов'!B184 -> Фарсудашавии ҷамъшуда – Мебел, лавозимоти идора, асбобҳо, инвентари истеҳсолӣ ва хоҷагидорӣ | G38: 25000 | I38: 1000 | K38: =G38+I38-H38 -> 26000
D39: ='План счетов'!A185 -> «1 42 500» | E39: ='План счетов'!B185 -> Фарсудашавии ҷамъшуда - ободонии замин
B40: Активный счёт | C40: Нематериальные активы | D40: ='План счетов'!A211 -> «1 49 100» | E40: ='План счетов'!B211 -> Таъминоти барномавӣ | H40: 15000 | J40: =F40+H40-I40 -> 15000
D41: ='План счетов'!A212 -> «1 49 200» | E41: ='План счетов'!B212 -> Веб-сайтҳо
...
