Workbook
Name База_Контр: [1]БазаКонтрагент!$B$2:$E$180
Name БазаиМаълумотТБ: #REF!
Name БазаиНЯХ: #REF!
Name БазаТБ: #REF!
Name БакияДарОхир: [1]БакияДарОхир!$B$8:$AMP$400
Name БакияДт_АввалСол: [1]Тартибдихи!$Q$8:$Q$400
Name БакияДт_ОхирСол: [1]Тартибдихи!$S$8:$S$400
Name БакияиБучет: #REF!
Name БакияиДарАввал: [1]БакияДарАввал!$B$8:$AMP$400
Name БакияиМахсус: #REF!
Name БакияиМахсус: #REF!
Name БакияКт_АввалСол: [1]Тартибдихи!$R$8:$R$400
Name БакияКт_ОхирСол: [1]Тартибдихи!$T$8:$T$400
Name ИчроишСмета: [1]ИчроишСмета!$B$12:$BMN$208
Name МаблагиГарБ: #REF!
Name ОстК_ДебетБ: '[2]5.Тартибдихи'!$H$7:$H$1102
Name ОстК_ДебетБ: #REF!
Name ОстК_ДебетМ: '[2]5.Тартибдихи'!$J$7:$J$1102
Name ОстК_ДебетМ: #REF!
Name ОстК_КредитБ: '[2]5.Тартибдихи'!$I$7:$I$1102
Name ОстК_КредитБ: #REF!
Name ОстК_КредитМ: '[2]5.Тартибдихи'!$K$7:$K$1102
Name ОстК_КредитМ: #REF!
Name ОстН_ДебетБ: '[2]5.Тартибдихи'!$D$7:$D$1102
Name ОстН_ДебетБ: #REF!
Name ОстН_ДебетМ: '[2]5.Тартибдихи'!$F$7:$F$1102
Name ОстН_ДебетМ: #REF!
Name ОстН_КредитБ: '[2]5.Тартибдихи'!$E$7:$E$1102
Name ОстН_КредитБ: #REF!
Name ОстН_КредитМ: '[2]5.Тартибдихи'!$G$7:$G$1102
Name ОстН_КредитМ: #REF!
Name РакамиНЯХ: '[2]5.Тартибдихи'!$A$7:$A$1102
Name РакамиНЯХ: #REF!
Name РамзиНЯХ: '[2]5.Тартибдихи'!$C$7:$C$1102
Name РамзиНЯХ: #REF!
Name РМА_АввалиСол: [1]БакияДарАввал!$E$3:$AMP$3
Name РМА_Бучет: #REF!
Name РМА_Ичроиш: [1]ИчроишСмета!$E$4:$BMN$4
Name РМА_Махсус: #REF!
Name РМА_Махсус: #REF!
Name РМА_ОхириСол: [1]БакияДарОхир!$E$3:$AMP$3

Sheet Ш-5 (СВОД)
D2: Замимаи 12 ба Дастурамал оиди тахия ва пешниходи хисоботи молиявии солона ва даврӣ мутобиқи СХМБДТ аз чониби муассиса ва ташкилотхои бучети
B4: Шакли №5
B5: Ҳисобот доир ба иҷроиши сметаи даромадҳо ва хароҷотҳо
B8: Рамзи ГМБ: | D8: 10801001
B9: Номгӯи ГМБ: | D9: =#REF! -> #REF!
B10: Давраи ҳисоботӣ: | D10: 30 сентябри соли 2026
B11: Воҳиди ченак: | D11: Сомонӣ
B13: ДАРОМАДҲО
B14: Номгуи гуруҳбандии бучетӣ: | E14: Гуруҳбандии даромадҳо
B15: Рамзи дархости даромадҳо/нақшаи даромадҳо: | E15: -
B16: Номгуи дархости даромадҳо/нақшаи даромадҳо: | E16: -
B17: Рамзи сарчашмаи маблағгузорӣ/дохилшавӣ: | E17: 111
B18: Номгӯи сарчашмаи маблағгузорӣ/дохилшавӣ: | E18: Маблағҳои буҷети ҷумҳуриявӣ
B19: Рамзи ГБ | C19: Номгуи ГБ | D19: Нақшаи тасдиқшуда | E19: Нақшаи аниқкардашуда | F19: Даромадҳои кассавӣ | G19: Даромадҳои воқеӣ
B20: 1 | C20: 2 | D20: 3 | E20: 4 | F20: 5 | G20: 6
A21: =IF(SUM(D21:G21)>0,1,0) -> 0 | C21: Бақия ба аввал
A22: =IF(SUM(D22:G22)>0,1,0) -> 1 | B22: 1. | C22: ҲАМАГӢ ДАРОМАДҲО | D22: =D23+D72+D95 -> 13579 | E22: =E23+E72+E95 -> 13579 | F22: 5555 | G22: 5555
A23: =IF(SUM(D23:G23)>0,1,0) -> 0 | B23: 1.01. | C23: Воридоти андозҳо | D23: =SUM(D24:D71) -> 0 | E23: =SUM(E24:E71) -> 0 | F23: =SUM(F24:F71) -> 0 | G23: =SUM(G24:G71) -> 0
A24: =IF(SUM(D24:G24)>0,1,0) -> 0 | B24: 1.01.01. | C24: Андоз аз даромад ва андоз аз фоида | G24: =F24 -> 0
A25: =IF(SUM(D25:G25)>0,1,0) -> 0 | B25: 1.01.01.01 | C25: Андоз аз даромад
A26: =IF(SUM(D26:G26)>0,1,0) -> 0 | B26: 1.01.01.02 | C26: Андоз аз фоида
A27: =IF(SUM(D27:G27)>0,1,0) -> 0 | B27: 1.01.02 | C27: Андози иҷтимоӣ | G27: =F27 -> 0
A28: =IF(SUM(D28:G28)>0,1,0) -> 0 | B28: 1.01.02.01 | C28: Андози иҷтимоӣ (1% Ташкилоту муассисаҳои буҷетӣ) | G28: =F28 -> 0
A29: =IF(SUM(D29:G29)>0,1,0) -> 0 | B29: 1.01.02.02 | C29: Андози иҷтимоӣ (25% Ташкилоту муассисаҳои буҷетӣ) | G29: =F29 -> 0
A30: =IF(SUM(D30:G30)>0,1,0) -> 0 | B30: 1.01.03 | C30: Андоз аз молу мулки ғайриманкул | G30: =F30 -> 0
A31: =IF(SUM(D31:G31)>0,1,0) -> 0 | B31: 1.01.03.01 | C31: Андоз аз молу мулки ғаӣриманқул
A32: =IF(SUM(D32:G32)>0,1,0) -> 0 | B32: 1.01.03.02 | C32: Андози замин аз шахсони ҳуқуқи
A33: =IF(SUM(D33:G33)>0,1,0) -> 0 | B33: 1.01.03.03 | C33: Андози замин аз шахсони воқеъӣ
A34: =IF(SUM(D34:G34)>0,1,0) -> 0 | B34: 1.01.04 | C34: Андоз аз фуруш | G34: =F34 -> 0
A35: =IF(SUM(D35:G35)>0,1,0) -> 0 | B35: 1.01.04.01 | C35: Андоз аз фуруши нахи пахта | G35: =F35 -> 0
A36: =IF(SUM(D36:G36)>0,1,0) -> 0 | B36: 1.01.04.02 | C36: Андоз аз фуруши алюминиӣи аввала | G36: =F36 -> 0
A37: =IF(SUM(D37:G37)>0,1,0) -> 0 | B37: 1.01.05 | C37: Андоз аз арзиши иловашуда | G37: =F37 -> 0
A38: =IF(SUM(D38:G38)>0,1,0) -> 0 | B38: 1.01.05.01 | C38: Андоз аз арзиши иловашудаи дохилӣ
A39: =IF(SUM(D39:G39)>0,1,0) -> 0 | B39: 1.01.05.02 | C39: Андоз аз арзиши иловашудаи берунӣ | G39: =F39 -> 0
A40: =IF(SUM(D40:G40)>0,1,0) -> 0 | B40: 1.01.06. | C40: Андоз аз истифодабарандагони роҳҳои автомобилгард | G40: =F40 -> 0
A41: =IF(SUM(D41:G41)>0,1,0) -> 0 | B41: 1.01.06.01 | C41: Андоз аз истифодабарандагони роҳҳои автомобилгард
A42: =IF(SUM(D42:G42)>0,1,0) -> 0 | B42: 1.01.07. | C42: Низоми махсуси андозбандӣ | G42: =F42 -> 0
A43: =IF(SUM(D43:G43)>0,1,0) -> 0 | B43: 1.01.06.01 | C43: Низоми соддакардашудаи андозбанди барои истехсолкун махсулоти кишоварзӣ
A44: =IF(SUM(D44:G44)>0,1,0) -> 0 | B44: 1.01.06.02 | C44: Низоми махсуси андозбандӣ барои субъектхои бизнеси бозӣ
A45: =IF(SUM(D45:G45)>0,1,0) -> 0 | B45: 1.01.06.03 | C45: Низоми соддакардашудаи андозбанди барои субъектҳои соҳибкории хурд
...
